2023-04-13 09:58:37,852 INFO: Microblog startup [in C:\Users\Macie\Desktop\Euromind\app\__init__.py:70]
2023-04-13 10:21:14,437 INFO: Microblog startup [in C:\Users\Macie\Desktop\Euromind\app\__init__.py:70]
2023-04-13 10:21:23,709 INFO: Microblog startup [in C:\Users\Macie\Desktop\Euromind\app\__init__.py:70]
2023-04-13 10:45:31,302 INFO: Microblog startup [in C:\Users\Macie\Desktop\Euromind\app\__init__.py:70]
2023-04-13 10:56:54,809 INFO: Microblog startup [in C:\Users\Macie\Desktop\Euromind\app\__init__.py:70]
2023-04-13 10:57:03,226 INFO: Microblog startup [in C:\Users\Macie\Desktop\Euromind\app\__init__.py:70]
2023-04-13 11:01:31,433 INFO: Microblog startup [in C:\Users\Macie\Desktop\Euromind\app\__init__.py:70]
2023-04-13 11:14:54,345 INFO: Microblog startup [in C:\Users\Macie\Desktop\Euromind\app\__init__.py:70]
2023-04-13 11:14:56,202 ERROR: Exception on /index [GET] [in C:\Users\Macie\AppData\Local\Programs\Python\Python39\lib\site-packages\flask\app.py:1744]
Traceback (most recent call last):
  File "C:\Users\Macie\AppData\Local\Programs\Python\Python39\lib\site-packages\flask\app.py", line 2528, in wsgi_app
    response = self.full_dispatch_request()
  File "C:\Users\Macie\AppData\Local\Programs\Python\Python39\lib\site-packages\flask\app.py", line 1825, in full_dispatch_request
    rv = self.handle_user_exception(e)
  File "C:\Users\Macie\AppData\Local\Programs\Python\Python39\lib\site-packages\flask\app.py", line 1823, in full_dispatch_request
    rv = self.dispatch_request()
  File "C:\Users\Macie\AppData\Local\Programs\Python\Python39\lib\site-packages\flask\app.py", line 1799, in dispatch_request
    return self.ensure_sync(self.view_functions[rule.endpoint])(**view_args)
  File "C:\Users\Macie\AppData\Local\Programs\Python\Python39\lib\site-packages\flask_login\utils.py", line 290, in decorated_view
    return current_app.ensure_sync(func)(*args, **kwargs)
  File "C:\Users\Macie\Desktop\Euromind\app\routes.py", line 66, in index
    return render_template("index.html", title='Home Page', form=form, posts=posts)
  File "C:\Users\Macie\AppData\Local\Programs\Python\Python39\lib\site-packages\flask\templating.py", line 147, in render_template
    return _render(app, template, context)
  File "C:\Users\Macie\AppData\Local\Programs\Python\Python39\lib\site-packages\flask\templating.py", line 130, in _render
    rv = template.render(context)
  File "C:\Users\Macie\AppData\Local\Programs\Python\Python39\lib\site-packages\jinja2\environment.py", line 1301, in render
    self.environment.handle_exception()
  File "C:\Users\Macie\AppData\Local\Programs\Python\Python39\lib\site-packages\jinja2\environment.py", line 936, in handle_exception
    raise rewrite_traceback_stack(source=source)
  File "C:\Users\Macie\Desktop\Euromind\app\templates\index.html", line 13, in top-level template code
    <h1>Hi, {{ user.username }}!</h1>
  File "C:\Users\Macie\AppData\Local\Programs\Python\Python39\lib\site-packages\jinja2\environment.py", line 485, in getattr
    return getattr(obj, attribute)
jinja2.exceptions.UndefinedError: 'user' is undefined
2023-04-13 11:14:59,373 ERROR: Exception on /index [GET] [in C:\Users\Macie\AppData\Local\Programs\Python\Python39\lib\site-packages\flask\app.py:1744]
Traceback (most recent call last):
  File "C:\Users\Macie\AppData\Local\Programs\Python\Python39\lib\site-packages\flask\app.py", line 2528, in wsgi_app
    response = self.full_dispatch_request()
  File "C:\Users\Macie\AppData\Local\Programs\Python\Python39\lib\site-packages\flask\app.py", line 1825, in full_dispatch_request
    rv = self.handle_user_exception(e)
  File "C:\Users\Macie\AppData\Local\Programs\Python\Python39\lib\site-packages\flask\app.py", line 1823, in full_dispatch_request
    rv = self.dispatch_request()
  File "C:\Users\Macie\AppData\Local\Programs\Python\Python39\lib\site-packages\flask\app.py", line 1799, in dispatch_request
    return self.ensure_sync(self.view_functions[rule.endpoint])(**view_args)
  File "C:\Users\Macie\AppData\Local\Programs\Python\Python39\lib\site-packages\flask_login\utils.py", line 290, in decorated_view
    return current_app.ensure_sync(func)(*args, **kwargs)
  File "C:\Users\Macie\Desktop\Euromind\app\routes.py", line 66, in index
    return render_template("index.html", title='Home Page', form=form, posts=posts)
  File "C:\Users\Macie\AppData\Local\Programs\Python\Python39\lib\site-packages\flask\templating.py", line 147, in render_template
    return _render(app, template, context)
  File "C:\Users\Macie\AppData\Local\Programs\Python\Python39\lib\site-packages\flask\templating.py", line 130, in _render
    rv = template.render(context)
  File "C:\Users\Macie\AppData\Local\Programs\Python\Python39\lib\site-packages\jinja2\environment.py", line 1301, in render
    self.environment.handle_exception()
  File "C:\Users\Macie\AppData\Local\Programs\Python\Python39\lib\site-packages\jinja2\environment.py", line 936, in handle_exception
    raise rewrite_traceback_stack(source=source)
  File "C:\Users\Macie\Desktop\Euromind\app\templates\index.html", line 13, in top-level template code
    <h1>Hi, {{ user.username }}!</h1>
  File "C:\Users\Macie\AppData\Local\Programs\Python\Python39\lib\site-packages\jinja2\environment.py", line 485, in getattr
    return getattr(obj, attribute)
jinja2.exceptions.UndefinedError: 'user' is undefined
2023-04-13 11:15:01,953 ERROR: Exception on /index [GET] [in C:\Users\Macie\AppData\Local\Programs\Python\Python39\lib\site-packages\flask\app.py:1744]
Traceback (most recent call last):
  File "C:\Users\Macie\AppData\Local\Programs\Python\Python39\lib\site-packages\flask\app.py", line 2528, in wsgi_app
    response = self.full_dispatch_request()
  File "C:\Users\Macie\AppData\Local\Programs\Python\Python39\lib\site-packages\flask\app.py", line 1825, in full_dispatch_request
    rv = self.handle_user_exception(e)
  File "C:\Users\Macie\AppData\Local\Programs\Python\Python39\lib\site-packages\flask\app.py", line 1823, in full_dispatch_request
    rv = self.dispatch_request()
  File "C:\Users\Macie\AppData\Local\Programs\Python\Python39\lib\site-packages\flask\app.py", line 1799, in dispatch_request
    return self.ensure_sync(self.view_functions[rule.endpoint])(**view_args)
  File "C:\Users\Macie\AppData\Local\Programs\Python\Python39\lib\site-packages\flask_login\utils.py", line 290, in decorated_view
    return current_app.ensure_sync(func)(*args, **kwargs)
  File "C:\Users\Macie\Desktop\Euromind\app\routes.py", line 66, in index
    return render_template("index.html", title='Home Page', form=form, posts=posts)
  File "C:\Users\Macie\AppData\Local\Programs\Python\Python39\lib\site-packages\flask\templating.py", line 147, in render_template
    return _render(app, template, context)
  File "C:\Users\Macie\AppData\Local\Programs\Python\Python39\lib\site-packages\flask\templating.py", line 130, in _render
    rv = template.render(context)
  File "C:\Users\Macie\AppData\Local\Programs\Python\Python39\lib\site-packages\jinja2\environment.py", line 1301, in render
    self.environment.handle_exception()
  File "C:\Users\Macie\AppData\Local\Programs\Python\Python39\lib\site-packages\jinja2\environment.py", line 936, in handle_exception
    raise rewrite_traceback_stack(source=source)
  File "C:\Users\Macie\Desktop\Euromind\app\templates\index.html", line 13, in top-level template code
    <h1>Hi, {{ user.username }}!</h1>
  File "C:\Users\Macie\AppData\Local\Programs\Python\Python39\lib\site-packages\jinja2\environment.py", line 485, in getattr
    return getattr(obj, attribute)
jinja2.exceptions.UndefinedError: 'user' is undefined
2023-04-13 11:15:07,631 ERROR: Exception on /index [GET] [in C:\Users\Macie\AppData\Local\Programs\Python\Python39\lib\site-packages\flask\app.py:1744]
Traceback (most recent call last):
  File "C:\Users\Macie\AppData\Local\Programs\Python\Python39\lib\site-packages\flask\app.py", line 2528, in wsgi_app
    response = self.full_dispatch_request()
  File "C:\Users\Macie\AppData\Local\Programs\Python\Python39\lib\site-packages\flask\app.py", line 1825, in full_dispatch_request
    rv = self.handle_user_exception(e)
  File "C:\Users\Macie\AppData\Local\Programs\Python\Python39\lib\site-packages\flask\app.py", line 1823, in full_dispatch_request
    rv = self.dispatch_request()
  File "C:\Users\Macie\AppData\Local\Programs\Python\Python39\lib\site-packages\flask\app.py", line 1799, in dispatch_request
    return self.ensure_sync(self.view_functions[rule.endpoint])(**view_args)
  File "C:\Users\Macie\AppData\Local\Programs\Python\Python39\lib\site-packages\flask_login\utils.py", line 290, in decorated_view
    return current_app.ensure_sync(func)(*args, **kwargs)
  File "C:\Users\Macie\Desktop\Euromind\app\routes.py", line 66, in index
    return render_template("index.html", title='Home Page', form=form, posts=posts)
  File "C:\Users\Macie\AppData\Local\Programs\Python\Python39\lib\site-packages\flask\templating.py", line 147, in render_template
    return _render(app, template, context)
  File "C:\Users\Macie\AppData\Local\Programs\Python\Python39\lib\site-packages\flask\templating.py", line 130, in _render
    rv = template.render(context)
  File "C:\Users\Macie\AppData\Local\Programs\Python\Python39\lib\site-packages\jinja2\environment.py", line 1301, in render
    self.environment.handle_exception()
  File "C:\Users\Macie\AppData\Local\Programs\Python\Python39\lib\site-packages\jinja2\environment.py", line 936, in handle_exception
    raise rewrite_traceback_stack(source=source)
  File "C:\Users\Macie\Desktop\Euromind\app\templates\index.html", line 13, in top-level template code
    <h1>Hi, {{ user.username }}!</h1>
  File "C:\Users\Macie\AppData\Local\Programs\Python\Python39\lib\site-packages\jinja2\environment.py", line 485, in getattr
    return getattr(obj, attribute)
jinja2.exceptions.UndefinedError: 'user' is undefined
